Workbook

Sheet Instructions
A1: Stride Application Security Review — Questionnaire V3
A3: Interactive Excel Workbook with Live RSK Scoring
A5: PURPOSE
A6: This workbook assesses the security posture of applications within the Stride technology portfolio. Each question maps to Stride ISP/IISP policies, NIST CSF 2.0 subcategories, and, where applicable, FERPA and SOX §404 ITGC requirements.
A7: For each question the assessor selects exactly one answer from a dropdown. The workbook automatically computes the RSK measurement per question, the RSK aggregate per domain, and the overall questionnaire-level RSK.
A9: HOW TO COMPLETE
A10: 1. Go to the 'Questionnaire' tab.
A11: 2. For each question, click the Answer cell (yellow column E) and choose from the dropdown.
A12: 3. The Measurement column (F) auto-calculates immediately.
A13: 4. Use the Notes column (G) for justifications or context.
A14: 5. When finished, review the 'Summary' tab for domain and overall risk scores.
A16: SCORING MODEL
... A38: Supersedes: ASR Checklist V2

Sheet Questionnaire
A1: # | B1: Domain | C1: Question | D1: Weight | E1: Answer ▼ | F1: Measurement | G1: Notes
A2: 1 | B2: Governance and Program Management | C2: Does the application have a designated security owner or steward? | D2: High | F2: =IF(E2="",0,IF(E2="Yes — named owner in CMDB",25,IF(E2="Yes — informal ownership",50,IF(E2="No — ownership not established",75,100)))*3/4)
A3: 2 | C3: Has a risk classification been assigned to this application? | D3: High | F3: =IF(E3="",0,IF(E3="Yes — High/Critical",25,IF(E3="Yes — Medium",50,IF(E3="Yes — Low",75,100)))*3/4)
A4: 3 | C4: Is the application included in the organization's security policy scope? | D4: Medium | F4: =IF(E4="",0,IF(E4="Yes — explicitly referenced",25,IF(E4="Yes — covered by umbrella policy",50,IF(E4="No — not in scope",75,100)))*2/4)
A5: 4 | C5: When was the last security review or assessment performed? | D5: High | F5: =IF(E5="",0,IF(E5="Within 6 months",25,IF(E5="6–12 months ago",50,IF(E5="More than 12 months ago",75,100)))*3/4)
A6: 5 | C6: Does the application have documented data flow diagrams? | D6: Medium | F6: =IF(E6="",0,IF(E6="Yes — current and reviewed",25,IF(E6="Yes — but outdated",50,IF(E6="No — not documented",75,100)))*2/4)
A7: 6 | C7: Has a RACI matrix been established for this application's security controls? | D7: High | F7: =IF(E7="",0,IF(E7="Yes — documented and current",25,IF(E7="Yes — but outdated or incomplete",50,IF(E7="No — roles informally understood",75,100)))*3/4)
A8: 7 | C8: Are escalation paths and notification responsibilities documented for security incidents involving this application? | D8: High | F8: =IF(E8="",0,IF(E8="Yes — RACI-aligned runbook with named contacts",25,IF(E8="Yes — general escalation via IRP",50,IF(E8="Partial — ad-hoc escalation only",75,100)))*3/4)
A9: 8 | C9: What is the business necessity classification for this application? | D9: Medium | F9: =IF(E9="",0,IF(E9="KTLO — operationally required (MUST)",25,IF(E9="Business need — supports key objectives (SHOULD)",50,IF(E9="Nice to have — productivity enhancement (MAY)",75,100)))*2/4)
A10: 9 | C10: Which teams and departments are authorized to use this application? | D10: Medium | F10: =IF(E10="",0,IF(E10="Enterprise-wide — all departments",25,IF(E10="Multiple departments — formally scoped",50,IF(E10="Single team or department",75,100)))*2/4)
A11: 10 | C11: Are productivity improvement estimates or benchmarks documented for this application? | D11: Medium | F11: =IF(E11="",0,IF(E11="Yes — quantified with baseline metrics and KPIs",25,IF(E11="Yes — qualitative estimates documented",50,IF(E11="Informal understanding only",75,100)))*2/4)
A12: 11 | C12: Has legal counsel reviewed this application's terms of service, data handling, and intellectual property implications? | D12: High | F12: =IF(E12="",0,IF(E12="Yes — reviewed and approved",25,IF(E12="Yes — reviewed with conditions or caveats",50,IF(E12="Review requested but not completed",75,100)))*3/4)
A13: 12 | C13: Has the application been reviewed and approved through the enterprise architecture governance process? | D13: High | F13: =IF(E13="",0,IF(E13="Yes — approved with defined boundaries and controls",25,IF(E13="Yes — approved for limited or pilot use",50,IF(E13="Under review",75,100)))*3/4)
A14: 13 | B14: Identity and Access Management | C14: What authentication mechanism does the application use? | D14: Critical | F14: =IF(E14="",0,IF(E14="SSO with MFA (Entra ID)",25,IF(E14="SSO without MFA",50,IF(E14="Local authentication with MFA",75,100)))*4/4)
A15: 14 | C15: Are user roles and permissions based on the principle of least privilege? | D15: High | F15: =IF(E15="",0,IF(E15="Yes — RBAC/ABAC enforced",25,IF(E15="Partially — some roles over-privileged",50,IF(E15="No — broad access grants",75,100)))*3/4)
A16: 15 | C16: How are service accounts and API keys managed? | D16: Critical | F16: =IF(E16="",0,IF(E16="Vault/managed identities with rotation",25,IF(E16="Stored securely with manual rotation",50,IF(E16="Hard-coded or shared credentials",75,100)))*4/4)
A17: 16 | C17: Is there automated provisioning/deprovisioning tied to HR events? | D17: High | F17: =IF(E17="",0,IF(E17="Yes — fully automated via SCIM/JIT",25,IF(E17="Partially automated",50,IF(E17="Manual process only",75,100)))*3/4)
A18: 17 | C18: Are access reviews performed periodically? | D18: High | F18: =IF(E18="",0,IF(E18="Quarterly or more frequently",25,IF(E18="Semi-annually",50,IF(E18="Annually",75,100)))*3/4)
A19: 18 | B19: Data Protection and Privacy | C19: Does the application process, store, or transmit student education records (FERPA-protected data)? | D19: Critical | F19: =IF(E19="",0,IF(E19="Yes — primary function",25,IF(E19="Yes — incidental processing",50,IF(E19="No — no education records",75,100)))*4/4)
A20: 19 | C20: Is data encrypted at rest? | D20: High | F20: =IF(E20="",0,IF(E20="Yes — AES-256 or equivalent",25,IF(E20="Yes — platform-managed encryption",50,IF(E20="Partial encryption",75,100)))*3/4)
A21: 20 | C21: Is data encrypted in transit? | D21: Critical | F21: =IF(E21="",0,IF(E21="Yes — TLS 1.2+ enforced",25,IF(E21="Yes — TLS with older versions allowed",50,IF(E21="Partial — some endpoints unencrypted",75,100)))*4/4)
A22: 21 | C22: What is the data classification level of information processed? | D22: High | F22: =IF(E22="",0,IF(E22="Public",25,IF(E22="Internal / Confidential",50,IF(E22="Restricted / Highly Sensitive",75,100)))*3/4)
A23: 22 | C23: Are data retention and disposal procedures implemented? | D23: Medium | F23: =IF(E23="",0,IF(E23="Yes — automated lifecycle management",25,IF(E23="Yes — manual procedures documented",50,IF(E23="Partial — some data managed",75,100)))*2/4)
A24: 23 | C24: Does the application maintain disclosure records as required by FERPA §99.32? | D24: High | F24: =IF(E24="",0,IF(E24="Yes — automated logging",25,IF(E24="Yes — manual records",50,IF(E24="Not applicable (no education records)",75,100)))*3/4)
A25: 24 | B25: Secure Development and Change Management | C25: Is the application developed using a documented SDLC methodology? | D25: High | F25: =IF(E25="",0,IF(E25="Yes — with security gates",25,IF(E25="Yes — without explicit security gates",50,IF(E25="Informal development process",75,100)))*3/4)
A26: 25 | C26: Are SAST and/or SCA scans integrated into the CI/CD pipeline? | D26: Critical | F26: =IF(E26="",0,IF(E26="Yes — blocking on critical findings",25,IF(E26="Yes — advisory only",50,IF(E26="Manual scans only",75,100)))*4/4)
A27: 26 | C27: Is DAST or penetration testing performed? | D27: High | F27: =IF(E27="",0,IF(E27="Yes — automated DAST in CI/CD + annual pentest",25,IF(E27="Annual penetration test only",50,IF(E27="Ad-hoc testing",75,100)))*3/4)
A28: 27 | C28: Are development, test, and production environments segregated? | D28: High | F28: =IF(E28="",0,IF(E28="Yes — fully segregated with access controls",25,IF(E28="Partially segregated",50,IF(E28="Shared environments",75,100)))*3/4)
A29: 28 | C29: Is there a formal change approval process for production deployments? | D29: High | F29: =IF(E29="",0,IF(E29="Yes — CAB/change authority approval required",25,IF(E29="Yes — peer review only",50,IF(E29="No formal approval process",75,100)))*3/4)
A30: 29 | C30: Is the application managed through the enterprise endpoint or patch management system (e.g., Intune, SCCM), or does it require an out-of-band update mechanism? | D30: High | F30: =IF(E30="",0,IF(E30="Fully managed via enterprise MDM/SCCM",25,IF(E30="Partially managed — some updates out-of-band",50,IF(E30="Entirely out-of-band (CLI, manual, or vendor-pushed)",75,100)))*3/4)
A31: 30 | C31: Are human review and approval required before application outputs are used in production or decision-making? | D31: High | F31: =IF(E31="",0,IF(E31="Yes — mandatory human review with sign-off",25,IF(E31="Yes — sampling-based or risk-tiered review",50,IF(E31="No — outputs used directly without review",75,100)))*3/4)
A32: 31 | B32: Vulnerability and Threat Management | C32: Is the application included in vulnerability scanning scope? | D32: Critical | F32: =IF(E32="",0,IF(E32="Yes — authenticated scans weekly+",25,IF(E32="Yes — unauthenticated scans",50,IF(E32="Ad-hoc scanning only",75,100)))*4/4)
A33: 32 | C33: What is the SLA for remediating critical vulnerabilities? | D33: High | F33: =IF(E33="",0,IF(E33="7 days or fewer",25,IF(E33="8–30 days",50,IF(E33="31–90 days",75,100)))*3/4)
A34: 33 | C34: Is the application monitored for security events? | D34: High | F34: =IF(E34="",0,IF(E34="Yes — SIEM integration with alerting",25,IF(E34="Yes — log collection without alerting",50,IF(E34="Partial monitoring",75,100)))*3/4)
A35: 34 | C35: Does the application have a web application firewall (WAF)? | D35: Medium | F35: =IF(E35="",0,IF(E35="Yes — managed WAF with tuned rules",25,IF(E35="Yes — default WAF rules",50,IF(E35="No WAF — network firewall only",75,100)))*2/4)
A36: 35 | C36: Are detective controls implemented to identify unauthorized or anomalous use of this application? | D36: High | F36: =IF(E36="",0,IF(E36="Yes — automated detection with real-time alerting",25,IF(E36="Yes — log-based detection requiring manual review",50,IF(E36="Partial — some detection capabilities",75,100)))*3/4)
A37: 36 | C37: Are corrective controls defined to remediate or contain issues detected during application use? | D37: High | F37: =IF(E37="",0,IF(E37="Yes — automated remediation and rollback capabilities",25,IF(E37="Yes — documented manual corrective procedures",50,IF(E37="Partial — ad-hoc correction only",75,100)))*3/4)
A38: 37 | C38: Is application usage monitored with defined KPIs escalated to both team-level and enterprise-level analysis? | D38: Medium | F38: =IF(E38="",0,IF(E38="Yes — dashboards with KPIs at both levels",25,IF(E38="Yes — team-level metrics only",50,IF(E38="Partial — ad-hoc reporting",75,100)))*2/4)
A39: 38 | B39: Incident Response and Business Continuity | C39: Is the application covered by the incident response plan? | D39: High | F39: =IF(E39="",0,IF(E39="Yes — application-specific runbook",25,IF(E39="Yes — covered by general IRP",50,IF(E39="Partial coverage",75,100)))*3/4)
A40: 39 | C40: What is the Recovery Time Objective (RTO)? | D40: High | F40: =IF(E40="",0,IF(E40="1 hour or less",25,IF(E40="1–4 hours",50,IF(E40="4–24 hours",75,100)))*3/4)
...

Sheet Summary
A1: ASR Questionnaire V3 — Risk Assessment Summary
A2: Generated 2026-03-03
A4: Questions Answered: | B4: =COUNTIF(Questionnaire!$F$2:$F$49,">0") | C4: of | D4: 48
A6: Domain | B6: # Q | C6: Answered | D6: RSK Raw (0–134) | E6: Norm % (0–100) | F6: Rating | G6: Policy / CSF References
A7: Governance and Program Management | B7: 12 | C7: =COUNTIF(Questionnaire!$F$2:$F$13,">0") | D7: =IF(SUM(Questionnaire!$F$2:$F$13)=0,0,CEILING(LARGE(Questionnaire!$F$2:$F$13,1)+LARGE(Questionnaire!$F$2:$F$13,2)/4+LARGE(Questionnaire!$F$2:$F$13,3)/16+LARGE(Questionnaire!$F$2:$F$13,4)/64+LARGE(Questionnaire!$F$2:$F$13,5)/256+LARGE(Questionnaire!$F$2:$F$13,6)/1024+LARGE(Questionnaire!$F$2:$F$13,7)/4096+LARGE(Questionnaire!$F$2:$F$13,8)/16384+LARGE(Questionnaire!$F$2:$F$13,9)/65536+LARGE(Questionnaire!$F$2:$F$13,10)/262144+LARGE(Questionnaire!$F$2:$F$13,11)/1048576+LARGE(Questionnaire!$F$2:$F$13,12)/4194304,1)) | E7: =IF(D7=0,0,MIN(100,ROUND(D7/134*100,1))) | F7: =IF(E7=0,"",IF(E7<=25,"Low",IF(E7<=50,"Moderate",IF(E7<=75,"Elevated","Critical")))) | G7: ISP 1.0, ISP 2.1, ISP 2.4, ISP 2.5 | GV.OC, GV.PO, GV.OV
A8: Identity and Access Management | B8: 5 | C8: =COUNTIF(Questionnaire!$F$14:$F$18,">0") | D8: =IF(SUM(Questionnaire!$F$14:$F$18)=0,0,CEILING(LARGE(Questionnaire!$F$14:$F$18,1)+LARGE(Questionnaire!$F$14:$F$18,2)/4+LARGE(Questionnaire!$F$14:$F$18,3)/16+LARGE(Questionnaire!$F$14:$F$18,4)/64+LARGE(Questionnaire!$F$14:$F$18,5)/256,1)) | E8: =IF(D8=0,0,MIN(100,ROUND(D8/134*100,1))) | F8: =IF(E8=0,"",IF(E8<=25,"Low",IF(E8<=50,"Moderate",IF(E8<=75,"Elevated","Critical")))) | G8: ISP 4.1, ISP 2.3, IISP 8.0 | PR.AA
A9: Data Protection and Privacy | B9: 6 | C9: =COUNTIF(Questionnaire!$F$19:$F$24,">0") | D9: =IF(SUM(Questionnaire!$F$19:$F$24)=0,0,CEILING(LARGE(Questionnaire!$F$19:$F$24,1)+LARGE(Questionnaire!$F$19:$F$24,2)/4+LARGE(Questionnaire!$F$19:$F$24,3)/16+LARGE(Questionnaire!$F$19:$F$24,4)/64+LARGE(Questionnaire!$F$19:$F$24,5)/256+LARGE(Questionnaire!$F$19:$F$24,6)/1024,1)) | E9: =IF(D9=0,0,MIN(100,ROUND(D9/134*100,1))) | F9: =IF(E9=0,"",IF(E9<=25,"Low",IF(E9<=50,"Moderate",IF(E9<=75,"Elevated","Critical")))) | G9: ISP 4.3, IISP 2.0, IISP 3.0 | PR.DS
A10: Secure Development and Change Management | B10: 7 | C10: =COUNTIF(Questionnaire!$F$25:$F$31,">0") | D10: =IF(SUM(Questionnaire!$F$25:$F$31)=0,0,CEILING(LARGE(Questionnaire!$F$25:$F$31,1)+LARGE(Questionnaire!$F$25:$F$31,2)/4+LARGE(Questionnaire!$F$25:$F$31,3)/16+LARGE(Questionnaire!$F$25:$F$31,4)/64+LARGE(Questionnaire!$F$25:$F$31,5)/256+LARGE(Questionnaire!$F$25:$F$31,6)/1024+LARGE(Questionnaire!$F$25:$F$31,7)/4096,1)) | E10: =IF(D10=0,0,MIN(100,ROUND(D10/134*100,1))) | F10: =IF(E10=0,"",IF(E10<=25,"Low",IF(E10<=50,"Moderate",IF(E10<=75,"Elevated","Critical")))) | G10: ISP 4.4, IISP 9.0 | PR.PS
A11: Vulnerability and Threat Management | B11: 7 | C11: =COUNTIF(Questionnaire!$F$32:$F$38,">0") | D11: =IF(SUM(Questionnaire!$F$32:$F$38)=0,0,CEILING(LARGE(Questionnaire!$F$32:$F$38,1)+LARGE(Questionnaire!$F$32:$F$38,2)/4+LARGE(Questionnaire!$F$32:$F$38,3)/16+LARGE(Questionnaire!$F$32:$F$38,4)/64+LARGE(Questionnaire!$F$32:$F$38,5)/256+LARGE(Questionnaire!$F$32:$F$38,6)/1024+LARGE(Questionnaire!$F$32:$F$38,7)/4096,1)) | E11: =IF(D11=0,0,MIN(100,ROUND(D11/134*100,1))) | F11: =IF(E11=0,"",IF(E11<=25,"Low",IF(E11<=50,"Moderate",IF(E11<=75,"Elevated","Critical")))) | G11: IISP 7.0, ISP 3.2, ISP 5.1 | ID.RA, DE.CM
A12: Incident Response and Business Continuity | B12: 5 | C12: =COUNTIF(Questionnaire!$F$39:$F$43,">0") | D12: =IF(SUM(Questionnaire!$F$39:$F$43)=0,0,CEILING(LARGE(Questionnaire!$F$39:$F$43,1)+LARGE(Questionnaire!$F$39:$F$43,2)/4+LARGE(Questionnaire!$F$39:$F$43,3)/16+LARGE(Questionnaire!$F$39:$F$43,4)/64+LARGE(Questionnaire!$F$39:$F$43,5)/256,1)) | E12: =IF(D12=0,0,MIN(100,ROUND(D12/134*100,1))) | F12: =IF(E12=0,"",IF(E12<=25,"Low",IF(E12<=50,"Moderate",IF(E12<=75,"Elevated","Critical")))) | G12: ISP 6.1, ISP 6.2, IISP 1.0, IISP 10.0 | RS.MA, RS.AN, RC.RP
A13: Third-Party and Supply Chain Risk | B13: 6 | C13: =COUNTIF(Questionnaire!$F$44:$F$49,">0") | D13: =IF(SUM(Questionnaire!$F$44:$F$49)=0,0,CEILING(LARGE(Questionnaire!$F$44:$F$49,1)+LARGE(Questionnaire!$F$44:$F$49,2)/4+LARGE(Questionnaire!$F$44:$F$49,3)/16+LARGE(Questionnaire!$F$44:$F$49,4)/64+LARGE(Questionnaire!$F$44:$F$49,5)/256+LARGE(Questionnaire!$F$44:$F$49,6)/1024,1)) | E13: =IF(D13=0,0,MIN(100,ROUND(D13/134*100,1))) | F13: =IF(E13=0,"",IF(E13<=25,"Low",IF(E13<=50,"Moderate",IF(E13<=75,"Elevated","Critical")))) | G13: ISP 2.6 | GV.SC
A14: OVERALL | B14: 48 | C14: =COUNTIF(Questionnaire!$F$2:$F$49,">0") | D14: =IF(SUM(Questionnaire!$F$2:$F$49)=0,0,CEILING(LARGE(Questionnaire!$F$2:$F$49,1)+LARGE(Questionnaire!$F$2:$F$49,2)/4+LARGE(Questionnaire!$F$2:$F$49,3)/16+LARGE(Questionnaire!$F$2:$F$49,4)/64+LARGE(Questionnaire!$F$2:$F$49,5)/256+LARGE(Questionnaire!$F$2:$F$49,6)/1024+LARGE(Questionnaire!$F$2:$F$49,7)/4096+LARGE(Questionnaire!$F$2:$F$49,8)/16384+LARGE(Questionnaire!$F$2:$F$49,9)/65536+LARGE(Questionnaire!$F$2:$F$49,10)/262144+LARGE(Questionnaire!$F$2:$F$49,11)/1048576+LARGE(Questionnaire!$F$2:$F$49,12)/4194304,1)) | E14: =IF(D14=0,0,MIN(100,ROUND(D14/134*100,1))) | F14: =IF(E14=0,"",IF(E14<=25,"Low",IF(E14<=50,"Moderate",IF(E14<=75,"Elevated","Critical"))))
A16: Risk Rating Scale
A17: 0–25% | B17: Low | C17: Strong posture — controls mature and effective
A18: 26–50% | B18: Moderate | C18: Adequate — minor gaps with compensating controls
A19: 51–75% | B19: Elevated | C19: Material gaps requiring remediation plans
A20: 76–100% | B20: Critical | C20: Fundamental controls missing or ineffective
A22: Application Information
A23: Application Name:
A24: Business Owner:
A25: Technical Owner:
A26: CMDB ID:
A27: Risk Classification:
A28: Assessment Date:
A29: Assessor:

Sheet Scoring Model
A1: RSK/STORM Scoring Model — Technical Reference
A3: This sheet documents the proprietary scoring model used in this workbook. It is included for internal reference and MUST NOT be shared with external parties.
A5: DIMINISHING-IMPACT COMPOSITE
A6: The RSK/STORM function computes a composite score where the most severe finding dominates and subsequent findings contribute progressively less:
A7: f(V, a) = ⌈Σ_{j=0}^{n-1} V_j / a^j⌉
A8: where V is sorted descending and a = 4 (damping base).
A9: Contributions: j=0 → 100%, j=1 → 25%, j=2 → 6.25%, j=3 → 1.56%, ...
A10: Theoretical max: 100 × 4/(4-1) = 133.33 → ⌈134⌉
A12: PER-QUESTION MEASUREMENT
A13: raw_score = ⌈100 × choice_position / n_choices⌉
A14: measurement = raw_score × (weight_value / 4)
A15: Choice 1 is the best answer (lowest score); choice N is the worst (highest score).
... A49: =MIN(100, ROUND(rsk_raw / 134 × 100, 1))
